2016-10-03 14:32:54,386 [Thread-2:12744] [django.request:124] [ERROR]- Internal Server Error: /
Traceback (most recent call last):
  File "D:\Programs\Python\Python35\lib\site-packages\django\core\handlers\exception.py", line 39, in inner
    response = get_response(request)
  File "D:\Programs\Python\Python35\lib\site-packages\django\core\handlers\base.py", line 187, in _get_response
    response = self.process_exception_by_middleware(e, request)
  File "D:\Programs\Python\Python35\lib\site-packages\django\core\handlers\base.py", line 185, in _get_response
    response = wrapped_callback(request, *callback_args, **callback_kwargs)
  File "D:\Django\sBlog\Blog\views.py", line 16, in index
    return render (request,'index.html',locals())
  File "D:\Programs\Python\Python35\lib\site-packages\django\shortcuts.py", line 30, in render
    content = loader.render_to_string(template_name, context, request, using=using)
  File "D:\Programs\Python\Python35\lib\site-packages\django\template\loader.py", line 67, in render_to_string
    template = get_template(template_name, using=using)
  File "D:\Programs\Python\Python35\lib\site-packages\django\template\loader.py", line 21, in get_template
    return engine.get_template(template_name)
  File "D:\Programs\Python\Python35\lib\site-packages\django\template\backends\django.py", line 39, in get_template
    return Template(self.engine.get_template(template_name), self)
  File "D:\Programs\Python\Python35\lib\site-packages\django\template\engine.py", line 160, in get_template
    template, origin = self.find_template(template_name)
  File "D:\Programs\Python\Python35\lib\site-packages\django\template\engine.py", line 134, in find_template
    name, template_dirs=dirs, skip=skip,
  File "D:\Programs\Python\Python35\lib\site-packages\django\template\loaders\base.py", line 44, in get_template
    contents, origin, origin.template_name, self.engine,
  File "D:\Programs\Python\Python35\lib\site-packages\django\template\base.py", line 191, in __init__
    self.nodelist = self.compile_nodelist()
  File "D:\Programs\Python\Python35\lib\site-packages\django\template\base.py", line 233, in compile_nodelist
    return parser.parse()
  File "D:\Programs\Python\Python35\lib\site-packages\django\template\base.py", line 489, in parse
    raise self.error(token, e)
  File "D:\Programs\Python\Python35\lib\site-packages\django\template\base.py", line 487, in parse
    filter_expression = self.compile_filter(token.contents)
  File "D:\Programs\Python\Python35\lib\site-packages\django\template\base.py", line 603, in compile_filter
    return FilterExpression(token, self)
  File "D:\Programs\Python\Python35\lib\site-packages\django\template\base.py", line 703, in __init__
    "from '%s'" % (token[upto:], token))
django.template.exceptions.TemplateSyntaxError: Could not parse the remainder: ' }' from 'SITE_NAME }'
2016-10-03 14:33:13,454 [Thread-8:13460] [django.request:124] [ERROR]- Internal Server Error: /
Traceback (most recent call last):
  File "D:\Programs\Python\Python35\lib\site-packages\django\core\handlers\exception.py", line 39, in inner
    response = get_response(request)
  File "D:\Programs\Python\Python35\lib\site-packages\django\core\handlers\base.py", line 187, in _get_response
    response = self.process_exception_by_middleware(e, request)
  File "D:\Programs\Python\Python35\lib\site-packages\django\core\handlers\base.py", line 185, in _get_response
    response = wrapped_callback(request, *callback_args, **callback_kwargs)
  File "D:\Django\sBlog\Blog\views.py", line 16, in index
    return render (request,'index.html',locals())
  File "D:\Programs\Python\Python35\lib\site-packages\django\shortcuts.py", line 30, in render
    content = loader.render_to_string(template_name, context, request, using=using)
  File "D:\Programs\Python\Python35\lib\site-packages\django\template\loader.py", line 68, in render_to_string
    return template.render(context, request)
  File "D:\Programs\Python\Python35\lib\site-packages\django\template\backends\django.py", line 66, in render
    return self.template.render(context)
  File "D:\Programs\Python\Python35\lib\site-packages\django\template\base.py", line 206, in render
    with context.bind_template(self):
  File "D:\Programs\Python\Python35\lib\contextlib.py", line 59, in __enter__
    return next(self.gen)
  File "D:\Programs\Python\Python35\lib\site-packages\django\template\context.py", line 232, in bind_template
    processors = (template.engine.template_context_processors +
  File "D:\Programs\Python\Python35\lib\site-packages\django\utils\functional.py", line 35, in __get__
    res = instance.__dict__[self.name] = self.func(instance)
  File "D:\Programs\Python\Python35\lib\site-packages\django\template\engine.py", line 91, in template_context_processors
    return tuple(import_string(path) for path in context_processors)
  File "D:\Programs\Python\Python35\lib\site-packages\django\template\engine.py", line 91, in <genexpr>
    return tuple(import_string(path) for path in context_processors)
  File "D:\Programs\Python\Python35\lib\site-packages\django\utils\module_loading.py", line 20, in import_string
    module = import_module(module_path)
  File "D:\Programs\Python\Python35\lib\importlib\__init__.py", line 126, in import_module
    return _bootstrap._gcd_import(name[level:], package, level)
  File "<frozen importlib._bootstrap>", line 986, in _gcd_import
  File "<frozen importlib._bootstrap>", line 969, in _find_and_load
  File "<frozen importlib._bootstrap>", line 944, in _find_and_load_unlocked
  File "<frozen importlib._bootstrap>", line 222, in _call_with_frames_removed
  File "<frozen importlib._bootstrap>", line 986, in _gcd_import
  File "<frozen importlib._bootstrap>", line 969, in _find_and_load
  File "<frozen importlib._bootstrap>", line 956, in _find_and_load_unlocked
ImportError: No module named 'blog'
2016-10-03 14:33:14,797 [Thread-9:13464] [django.request:124] [ERROR]- Internal Server Error: /
Traceback (most recent call last):
  File "D:\Programs\Python\Python35\lib\site-packages\django\core\handlers\exception.py", line 39, in inner
    response = get_response(request)
  File "D:\Programs\Python\Python35\lib\site-packages\django\core\handlers\base.py", line 187, in _get_response
    response = self.process_exception_by_middleware(e, request)
  File "D:\Programs\Python\Python35\lib\site-packages\django\core\handlers\base.py", line 185, in _get_response
    response = wrapped_callback(request, *callback_args, **callback_kwargs)
  File "D:\Django\sBlog\Blog\views.py", line 16, in index
    return render (request,'index.html',locals())
  File "D:\Programs\Python\Python35\lib\site-packages\django\shortcuts.py", line 30, in render
    content = loader.render_to_string(template_name, context, request, using=using)
  File "D:\Programs\Python\Python35\lib\site-packages\django\template\loader.py", line 68, in render_to_string
    return template.render(context, request)
  File "D:\Programs\Python\Python35\lib\site-packages\django\template\backends\django.py", line 66, in render
    return self.template.render(context)
  File "D:\Programs\Python\Python35\lib\site-packages\django\template\base.py", line 206, in render
    with context.bind_template(self):
  File "D:\Programs\Python\Python35\lib\contextlib.py", line 59, in __enter__
    return next(self.gen)
  File "D:\Programs\Python\Python35\lib\site-packages\django\template\context.py", line 232, in bind_template
    processors = (template.engine.template_context_processors +
  File "D:\Programs\Python\Python35\lib\site-packages\django\utils\functional.py", line 35, in __get__
    res = instance.__dict__[self.name] = self.func(instance)
  File "D:\Programs\Python\Python35\lib\site-packages\django\template\engine.py", line 91, in template_context_processors
    return tuple(import_string(path) for path in context_processors)
  File "D:\Programs\Python\Python35\lib\site-packages\django\template\engine.py", line 91, in <genexpr>
    return tuple(import_string(path) for path in context_processors)
  File "D:\Programs\Python\Python35\lib\site-packages\django\utils\module_loading.py", line 20, in import_string
    module = import_module(module_path)
  File "D:\Programs\Python\Python35\lib\importlib\__init__.py", line 126, in import_module
    return _bootstrap._gcd_import(name[level:], package, level)
  File "<frozen importlib._bootstrap>", line 986, in _gcd_import
  File "<frozen importlib._bootstrap>", line 969, in _find_and_load
  File "<frozen importlib._bootstrap>", line 944, in _find_and_load_unlocked
  File "<frozen importlib._bootstrap>", line 222, in _call_with_frames_removed
  File "<frozen importlib._bootstrap>", line 986, in _gcd_import
  File "<frozen importlib._bootstrap>", line 969, in _find_and_load
  File "<frozen importlib._bootstrap>", line 956, in _find_and_load_unlocked
ImportError: No module named 'blog'
2016-10-03 14:33:49,193 [Thread-2:13932] [django.request:124] [ERROR]- Internal Server Error: /
Traceback (most recent call last):
  File "D:\Programs\Python\Python35\lib\site-packages\django\core\handlers\exception.py", line 39, in inner
    response = get_response(request)
  File "D:\Programs\Python\Python35\lib\site-packages\django\core\handlers\base.py", line 187, in _get_response
    response = self.process_exception_by_middleware(e, request)
  File "D:\Programs\Python\Python35\lib\site-packages\django\core\handlers\base.py", line 185, in _get_response
    response = wrapped_callback(request, *callback_args, **callback_kwargs)
  File "D:\Django\sBlog\Blog\views.py", line 16, in index
    return render (request,'index.html',locals())
  File "D:\Programs\Python\Python35\lib\site-packages\django\shortcuts.py", line 30, in render
    content = loader.render_to_string(template_name, context, request, using=using)
  File "D:\Programs\Python\Python35\lib\site-packages\django\template\loader.py", line 68, in render_to_string
    return template.render(context, request)
  File "D:\Programs\Python\Python35\lib\site-packages\django\template\backends\django.py", line 66, in render
    return self.template.render(context)
  File "D:\Programs\Python\Python35\lib\site-packages\django\template\base.py", line 206, in render
    with context.bind_template(self):
  File "D:\Programs\Python\Python35\lib\contextlib.py", line 59, in __enter__
    return next(self.gen)
  File "D:\Programs\Python\Python35\lib\site-packages\django\template\context.py", line 236, in bind_template
    updates.update(processor(self.request))
TypeError: global_setting() takes 0 positional arguments but 1 was given
2016-10-03 14:33:50,031 [Thread-3:13936] [django.request:124] [ERROR]- Internal Server Error: /
Traceback (most recent call last):
  File "D:\Programs\Python\Python35\lib\site-packages\django\core\handlers\exception.py", line 39, in inner
    response = get_response(request)
  File "D:\Programs\Python\Python35\lib\site-packages\django\core\handlers\base.py", line 187, in _get_response
    response = self.process_exception_by_middleware(e, request)
  File "D:\Programs\Python\Python35\lib\site-packages\django\core\handlers\base.py", line 185, in _get_response
    response = wrapped_callback(request, *callback_args, **callback_kwargs)
  File "D:\Django\sBlog\Blog\views.py", line 16, in index
    return render (request,'index.html',locals())
  File "D:\Programs\Python\Python35\lib\site-packages\django\shortcuts.py", line 30, in render
    content = loader.render_to_string(template_name, context, request, using=using)
  File "D:\Programs\Python\Python35\lib\site-packages\django\template\loader.py", line 68, in render_to_string
    return template.render(context, request)
  File "D:\Programs\Python\Python35\lib\site-packages\django\template\backends\django.py", line 66, in render
    return self.template.render(context)
  File "D:\Programs\Python\Python35\lib\site-packages\django\template\base.py", line 206, in render
    with context.bind_template(self):
  File "D:\Programs\Python\Python35\lib\contextlib.py", line 59, in __enter__
    return next(self.gen)
  File "D:\Programs\Python\Python35\lib\site-packages\django\template\context.py", line 236, in bind_template
    updates.update(processor(self.request))
TypeError: global_setting() takes 0 positional arguments but 1 was given
2016-10-03 14:36:59,890 [Thread-2:11692] [django.request:124] [ERROR]- Internal Server Error: /
Traceback (most recent call last):
  File "D:\Programs\Python\Python35\lib\site-packages\django\core\handlers\exception.py", line 39, in inner
    response = get_response(request)
  File "D:\Programs\Python\Python35\lib\site-packages\django\core\handlers\base.py", line 187, in _get_response
    response = self.process_exception_by_middleware(e, request)
  File "D:\Programs\Python\Python35\lib\site-packages\django\core\handlers\base.py", line 185, in _get_response
    response = wrapped_callback(request, *callback_args, **callback_kwargs)
  File "D:\Django\sBlog\Blog\views.py", line 16, in index
    return render (request,'index.html',locals())
  File "D:\Programs\Python\Python35\lib\site-packages\django\shortcuts.py", line 30, in render
    content = loader.render_to_string(template_name, context, request, using=using)
  File "D:\Programs\Python\Python35\lib\site-packages\django\template\loader.py", line 68, in render_to_string
    return template.render(context, request)
  File "D:\Programs\Python\Python35\lib\site-packages\django\template\backends\django.py", line 66, in render
    return self.template.render(context)
  File "D:\Programs\Python\Python35\lib\site-packages\django\template\base.py", line 206, in render
    with context.bind_template(self):
  File "D:\Programs\Python\Python35\lib\contextlib.py", line 59, in __enter__
    return next(self.gen)
  File "D:\Programs\Python\Python35\lib\site-packages\django\template\context.py", line 236, in bind_template
    updates.update(processor(self.request))
TypeError: global_setting() takes 0 positional arguments but 1 was given
